Workbook

Sheet Instructions
A1: Phase 1 systematic review workbook
A2: Follows the Phase 1 Systematic Review Protocol doc. Yellow cells are for you to fill in.
A3: Search log: one row per search per database. Paste the exact string you ran (database syntax differs), the date, the hit count and the export file name. These numbers feed the PRISMA flow diagram.
A4: Screening: import all exported records into Zotero, remove duplicates, then record title/abstract and full-text decisions (I1-I5, E1-E5 codes from the protocol).
A5: Extraction: one row per included study. Copy key figures verbatim with the page number. Rows are pre-filled for the 146 sources cited in thesis draft v2 (reference number = draft v2 number).
A6: PRISMA counts: filled automatically from the Screening sheet.

Sheet Search log
A1: Search | B1: Mapping question | C1: Database | D1: Block combination | E1: Exact string used (paste) | F1: Fields | G1: Date run | H1: Hits | I1: Export file | J1: Notes
A2: S1 | B2: MQ1 | C2: IEEE Xplore | D2: (A) AND (B) | F2: Title, abstract, keywords
A3: S1 | B3: MQ1 | C3: ACM Digital Library | D3: (A) AND (B) | F3: Title, abstract, keywords
A4: S1 | B4: MQ1 | C4: Scopus | D4: (A) AND (B) | F4: Title, abstract, keywords
A5: S1 | B5: MQ1 | C5: Web of Science | D5: (A) AND (B) | F5: Title, abstract, keywords
A6: S1 | B6: MQ1 | C6: SpringerLink | D6: (A) AND (B) | F6: Title, abstract, keywords
A7: S1 | B7: MQ1 | C7: ScienceDirect | D7: (A) AND (B) | F7: Title, abstract, keywords
A8: S2 | B8: MQ2 | C8: IEEE Xplore | D8: (A) AND (C) | F8: Title, abstract, keywords
A9: S2 | B9: MQ2 | C9: ACM Digital Library | D9: (A) AND (C) | F9: Title, abstract, keywords
A10: S2 | B10: MQ2 | C10: Scopus | D10: (A) AND (C) | F10: Title, abstract, keywords
A11: S2 | B11: MQ2 | C11: Web of Science | D11: (A) AND (C) | F11: Title, abstract, keywords
A12: S2 | B12: MQ2 | C12: SpringerLink | D12: (A) AND (C) | F12: Title, abstract, keywords
A13: S2 | B13: MQ2 | C13: ScienceDirect | D13: (A) AND (C) | F13: Title, abstract, keywords
... A31: S5 | B31: MQ4, MQ5 | C31: ScienceDirect | D31: (E) AND ((A) OR "cyber-physical") | F31: Title, abstract, keywords
A33: Term blocks
A34: A | E34: "automated driving" OR "autonomous driving" OR "autonomous vehicle*" OR "automated vehicle*" OR "self-driving"
A35: B | E35: "operational design domain" OR "operational domain" OR "ODD specification" OR "ODD monitoring"
A36: C | E36: "safety requirement*" OR "requirement* formali*" OR "natural language requirement*" OR "requirement* traceab*"
A37: D | E37: "scenario generation" OR "scenario selection" OR "test scenario*" OR "scenario-based testing" OR "critical scenario*"
A38: E | E38: "quantum annealing" OR QAOA OR QUBO OR Ising OR "quantum optimi*" OR "quantum approximate optimization"
A39: F | E39: "test case generation" OR "test case selection" OR "test minimi*" OR "test suite" OR "regression testing"
A40: Total hits (all searches) | H40: =SUM(H2:H31)

Sheet Screening
A1: Record ID | B1: Title | C1: Year | D1: Source database(s) | E1: Duplicate? (Y/N) | F1: Title/abstract decision (Include/Exclude) | G1: Reason code (I1-I5 / E1-E5) | H1: Full-text decision (Include/Exclude) | I1: Full-text reason code | J1: Second reviewer decision | K1: Agreement (auto)
K2: =IF(OR(F2="",J2=""),"",IF(F2=J2,1,0))
K3: =IF(OR(F3="",J3=""),"",IF(F3=J3,1,0))
K4: =IF(OR(F4="",J4=""),"",IF(F4=J4,1,0))
K5: =IF(OR(F5="",J5=""),"",IF(F5=J5,1,0))
K6: =IF(OR(F6="",J6=""),"",IF(F6=J6,1,0))
K7: =IF(OR(F7="",J7=""),"",IF(F7=J7,1,0))
K8: =IF(OR(F8="",J8=""),"",IF(F8=J8,1,0))
K9: =IF(OR(F9="",J9=""),"",IF(F9=J9,1,0))
K10: =IF(OR(F10="",J10=""),"",IF(F10=J10,1,0))
K11: =IF(OR(F11="",J11=""),"",IF(F11=J11,1,0))
K12: =IF(OR(F12="",J12=""),"",IF(F12=J12,1,0))
K13: =IF(OR(F13="",J13=""),"",IF(F13=J13,1,0))
... K401: =IF(OR(F401="",J401=""),"",IF(F401=J401,1,0))

Sheet PRISMA counts
A1: Stage | B1: Count
A2: Records identified (all searches) | B2: ='Search log'!H40
A3: Duplicates removed | B3: =COUNTIF(Screening!E2:E401,"Y")
A4: Records screened (title/abstract) | B4: =COUNTA(Screening!A2:A401)-B3
A5: Excluded at title/abstract | B5: =COUNTIF(Screening!F2:F401,"Exclude")
A6: Full texts assessed | B6: =COUNTIF(Screening!F2:F401,"Include")
A7: Excluded at full text | B7: =COUNTIF(Screening!H2:H401,"Exclude")
A8: Included from database search | B8: =COUNTIF(Screening!H2:H401,"Include")
A9: Second-reviewer agreement on double-screened records (%) | B9: =IFERROR(AVERAGE(Screening!K2:K401),"")

Sheet Extraction
A1: Draft v2 ref no. | B1: Key | C1: IEEE reference | D1: Mapping question(s) | E1: Domain | F1: Input artefact | G1: Technique | H1: Traceability to requirements (Y/P/N) | I1: Evaluation type | J1: Hardware (QPU/simulator/classical) | K1: Key quantitative result (verbatim, with page) | L1: Limitations stated by authors | M1: Quality score (0-5)
A2: 1 | B2: D2 | C2: National Highway Traffic Safety Administration, Office of Defects Investigation, "ODI resume: Engineering analysis EA26002," Mar. 18, 2026. [Online]. Available: https://static.nhtsa.gov/odi/inv/2026/INOA-EA26002-10023.pdf
A3: 2 | B3: C37 | C3: Commission Implementing Regulation (EU) 2022/1426 of 5 August 2022 laying down rules for the application of Regulation (EU) 2019/2144 as regards uniform procedures and technical specifications for the type-approval of the automated driving system (ADS) of fully automated vehicles, Off. J. Eur. Union, 2022. | D3: MQ1 (corpus source)
A4: 3 | B4: D10 | C4: "Formalization of operational domain and operational design domain for automated vehicles," arXiv:2408.14481, 2024.
A5: 4 | B5: C1 | C5: M. Skoglund, F. Warg, A. Thorsén, H. Hansson, and S. Punnekkat, "Formalizing operational design domains with the Pkl language," arXiv:2509.02221, 2025. | D5: MQ1
A6: 5 | B6: C23 | C6: K. Elmaaroufi, D. Shanker, A. Cismaru, M. Vazquez-Chanlatte, A. Sangiovanni-Vincentelli, M. Zaharia, and S. A. Seshia, "Generating probabilistic scenario programs from natural language," arXiv:2405.03709, 2024. | D6: MQ2, MQ3, MQ5
A7: 6 | B7: C24 | C7: Y. Deng, J. Yao, Z. Tu, M. Zhang, X. Zheng, and T. Zhang, "TARGET: Automated scenario generation from traffic rules for testing autonomous vehicles," arXiv:2305.06018, 2023. | D7: MQ2, MQ3, MQ5
A8: 7 | B8: C19 | C8: A. Nayak, H. P. Timmapathini, V. Murali, K. Ponnalagu, V. G. Venkoparao, and A. Post, "Req2Spec: Transforming software requirements into formal specifications using natural language processing," in Requirements Engineering: Foundation for Software Quality (REFSQ 2022), Lecture Notes in Computer Science, vol. 13216. Cham, Switzerland: Springer, 2022, pp. 87-95, doi: 10.1007/978-3-030-98464-9_8. | D8: MQ2
A9: 8 | B9: C34 | C9: D. Giannakopoulou, T. Pressburger, A. Mavridou, and J. Schumann, "Automated formalization of structured natural language requirements," Inf. Softw. Technol., vol. 137, Art. no. 106590, 2021, doi: 10.1016/j.infsof.2021.106590. | D9: MQ2
A10: 9 | B10: C33 | C10: F. Klück, Y. Li, J. Tao, and F. Wotawa, "An empirical comparison of combinatorial testing and search-based testing in the context of automated and autonomous driving systems," Inf. Softw. Technol., vol. 160, Art. no. 107225, 2023, doi: 10.1016/j.infsof.2023.107225. | D10: MQ3, MQ4
A11: 10 | B11: D44 | C11: Taxonomy and Definitions for Terms Related to Driving Automation Systems for On-Road Motor Vehicles, SAE J3016_202104, SAE International, 2021.
A12: 11 | B12: D40 | C12: Road Vehicles - Functional Safety, ISO 26262:2018, International Organization for Standardization, Geneva, Switzerland, 2018.
A13: 12 | B13: D41 | C13: Road Vehicles - Safety of the Intended Functionality, ISO 21448:2022, International Organization for Standardization, Geneva, Switzerland, 2022.
A14: 13 | B14: D8 | C14: S. Mitra, C. Păsăreanu, P. Prabhakar, S. A. Seshia, R. Mangal, Y. Li, C. Watson, D. Gopinath, and H. Yu, "Formal verification techniques for vision-based autonomous systems - A survey," in Principles of Verification: Cycling the Probabilistic Landscape, Lecture Notes in Computer Science, vol. 15262. Cham, Switzerland: Springer, 2025, doi: 10.1007/978-3-031-75778-5_5.
A15: 14 | B15: C21 | C15: S. Riedmaier, T. Ponn, D. Ludwig, B. Schick, and F. Diermeyer, "Survey on scenario-based safety assessment of automated vehicles," IEEE Access, vol. 8, pp. 87456-87477, 2020, doi: 10.1109/ACCESS.2020.2993730. | D15: MQ3
A16: 15 | B16: C31 | C16: C. Amersbach and H. Winner, "Defining required and feasible test coverage for scenario-based validation of highly automated vehicles," in Proc. 22nd IEEE Intelligent Transportation Systems Conf. (ITSC), Auckland, New Zealand, 2019. | D16: MQ3
A17: 16 | B17: D17 | C17: H. Araujo, X. Wang, M. Mousavi, and S. Ali, "Using quantum annealing to generate test cases for cyber-physical systems," arXiv:2504.21684, 2025.
A18: 17 | B18: D18 | C18: A. Trovato, M. Beseda, and D. Di Nucci, "A preliminary investigation on the usage of quantum approximate optimization algorithms for test case selection," arXiv:2504.18955, 2025.
A19: 18 | B19: D19 | C19: X. Wang, A. Muqeet, T. Yue, S. Ali, and P. Arcaini, "Test case minimization with quantum annealers," ACM Trans. Softw. Eng. Methodol., doi: 10.1145/3680467. arXiv:2308.05505.
A20: 19 | B20: C14 | C20: A. Trovato, M. De Stefano, F. Pecorelli, D. Di Nucci, and A. De Lucia, "Reformulating regression test suite optimization using quantum annealing - an empirical study," Int. J. Softw. Tools Technol. Transf., doi: 10.1007/s10009-024-00775-w. arXiv:2411.15963. | D20: MQ4
A21: 20 | B21: D1 | C21: National Transportation Safety Board, "NTSB finds automation overreliance contributed to two fatal Ford BlueCruise crashes," Press Release NR20260331, Mar. 31, 2026. [Online]. Available: https://www.ntsb.gov/news/press-releases/Pages/NR20260331.aspx
A22: 21 | B22: D7 | C22: National Transportation Safety Board, "Investigation HWY26FH008: Automated vehicle strikes pedestrian in school zone, Santa Monica, California," Jan. 23, 2026. [Online]. Available: https://www.ntsb.gov/investigations/Pages/HWY26FH008.aspx
A23: 22 | B23: WAYMOREC | C23: Waymo LLC, "Part 573 safety recall report 25E-084," National Highway Traffic Safety Administration, Dec. 2025. [Online]. Available: https://static.nhtsa.gov/odi/rcl/2025/RCLRPT-25E084-7732.pdf
A24: 23 | B24: D4 | C24: National Highway Traffic Safety Administration, "Consent order: Cruise crash reporting," Press release, Sep. 30, 2024. [Online]. Available: https://www.nhtsa.gov/press-releases/consent-order-cruise-crash-reporting
A25: 24 | B25: D3 | C25: J. Stempel and A. Roy, "Tesla ordered by Florida jury to pay $243 million in fatal Autopilot crash," Reuters, Aug. 1, 2025.
A26: 25 | B26: KITCH | C26: B. Kitchenham and S. Charters, "Guidelines for performing systematic literature reviews in software engineering," Keele Univ. and Durham Univ., Tech. Rep. EBSE-2007-01, 2007.
A27: 26 | B27: PETER | C27: K. Petersen, S. Vakkalanka, and L. Kuzniarz, "Guidelines for conducting systematic mapping studies in software engineering: An update," Inf. Softw. Technol., vol. 64, pp. 1-18, 2015.
A28: 27 | B28: WOHLIN | C28: C. Wohlin, "Guidelines for snowballing in systematic literature studies and a replication in software engineering," in Proc. 18th Int. Conf. Evaluation and Assessment in Software Engineering (EASE), 2014, doi: 10.1145/2601248.2601268.
A29: 28 | B29: PRISMA | C29: M. J. Page et al., "The PRISMA 2020 statement: An updated guideline for reporting systematic reviews," BMJ, vol. 372, Art. no. n71, 2021.
A30: 29 | B30: D21 | C30: E. M. Clarke, "The birth of model checking," in 25 Years of Model Checking, Lecture Notes in Computer Science, vol. 5000. Berlin, Germany: Springer, 2008, pp. 1-26, doi: 10.1007/978-3-540-69850-0_1.
A31: 30 | B31: S64 | C31: M. Luckcuck, M. Farrell, L. A. Dennis, C. Dixon, and M. Fisher, "Formal specification and verification of autonomous robotic systems: A survey," ACM Comput. Surv., vol. 52, no. 5, pp. 1-41, 2019, doi: 10.1145/3342355.
A32: 31 | B32: S63 | C32: C. Menghi, C. Tsigkanos, P. Pelliccione, C. Ghezzi, and T. Berger, "Specification patterns for robotic missions," IEEE Trans. Softw. Eng., vol. 47, no. 10, pp. 2208-2224, 2021 (IEEE Xplore document 8859226).
... A39: 38 | B39: D66 | C39: Operational Design Domain (ODD) Taxonomy for an Automated Driving System (ADS) - Specification, BSI PAS 1883:2020, British Standards Institution, London, U.K., 2020.
A40: 39 | B40: C6 | C40: Road Vehicles - Test Scenarios for Automated Driving Systems - Specification for Operational Design Domain, ISO 34503:2023, International Organization for Standardization, Geneva, Switzerland, 2023. | D40: MQ1
A41: 40 | B41: C7 | C41: ASAM e.V., "ASAM OpenODD, version 1.0.0," Apr. 3, 2025. [Online]. Available: https://publications.pages.asam.net/standards/ASAM_OpenODD/ASAM_OpenODD/latest/specification/00_preface/00_introduction.html | D41: MQ1
A42: 41 | B42: C3 | C42: M. Aguirre Mehlhorn, A. Richter, and Y. A. W. Shardt, "Ruling the operational boundaries: A survey on operational design domains of autonomous driving systems," IFAC-PapersOnLine, vol. 56, no. 2, pp. 2202-2213, 2023, doi: 10.1016/j.ifacol.2023.10.1128. | D42: MQ1
A43: 42 | B43: C13 | C43: H. Xu, Y. Li, H. Qin, Y. Bian, S. Jiang, W. Que, and J. Man, "Ensuring safe operation of autonomous vehicle: A comprehensive survey of operational design condition," Accid. Anal. Prev., vol. 227, Art. no. 108366, 2026, doi: 10.1016/j.aap.2025.108366. | D43: MQ1
A44: 43 | B44: C2 | C44: D. Hillen, M. Lorenz, J. Reich, R. Adler, P. Wolf, S. A. Zafar, and A. Salvi, "Navigating the landscape of operational design domains: A comprehensive mapping study," Next Res., vol. 2, no. 4, Art. no. 101036, 2025, doi: 10.1016/j.nexres.2025.101036. | D44: MQ1, MQ3, MQ5
A45: 44 | B45: C11 | C45: M. Ito, "ODD description methods for automated driving vehicle and verifiability for safety," J. Univers. Comput. Sci., vol. 27, no. 8, pp. 796-810, 2021, doi: 10.3897/jucs.72333. | D45: MQ1
A46: 45 | B46: C5 | C46: L. Mendiboure, M. L. Benzagouta, D. Gruyer, T. Sylla, M. Adedjouma, and A. Hedhli, "Operational design domain for automated driving systems: Taxonomy definition and application," in Proc. IEEE Intelligent Vehicles Symp. (IV), 2023, doi: 10.1109/IV55152.2023.10186765. | D46: MQ1
...
